<?xml version="1.0"?>
<robot xmlns:xacro="http://www.ros.org/wiki/xacro" name="rover">

  <link name="foot"/>

  
  <joint name="base_joint" type="fixed">
    <parent link="foot"/>
    <child link="base_link"/>
    <origin xyz="0 0 0" rpy="0 0 0"/>
  </joint>

  <link name="base_link">
    <visual>
      <origin xyz="0 0 0" rpy="0 0 0"/>
      <geometry>
        <box size="0.6 0.4 0.15"/>
      </geometry>
      <material name="blue">
        <color rgba="0.0 0.0 0.8 1.0"/>
      </material>
    </visual>

    <collision>
      <origin xyz="0 0 0" rpy="0 0 0"/>
      <geometry>
        <box size="0.6 0.4 0.15"/>
      </geometry>
    </collision>

    <inertial>
      <origin xyz="0 0 0" rpy="0 0 0"/>
      <mass value="5.0"/>
      <inertia ixx="0.0785" ixy="0" ixz="0"
               iyy="0.1604" iyz="0"
               izz="0.2167"/>
    </inertial>
  </link>
  
  <xacro:macro name="wheel" params="name joint x y">
    <link name="${name}">
      <visual>
        <origin xyz="0 0 0" rpy="1.5708 0 0"/>
        <geometry><cylinder radius="0.1" length="0.05"/></geometry>
        <material name="black"><color rgba="0.1 0.1 0.1 1.0"/></material>
      </visual>

      <collision>
        <origin xyz="0 0 0" rpy="1.5708 0 0"/>
        <geometry><cylinder radius="0.1" length="0.05"/></geometry>
      </collision>
      
      <inertial>
        <origin xyz="0 0 0" rpy="0 0 0"/>
        <mass value="0.5"/>
        <inertia ixx="0.00135" ixy="0" ixz="0" iyy="0.0025" iyz="0" izz="0.00135"/>
      </inertial>
    </link>

    <joint name="${joint}" type="continuous">
      <parent link="base_link"/>
      <child  link="${name}"/>
      <origin xyz="${x} ${y} -0.075" rpy="0 0 0"/>
      <axis xyz="0 1 0"/>
    </joint>
  </xacro:macro>

  <xacro:wheel name="fl_wheel" joint="fl_joint" x="0.2"  y="0.225"/>
  <xacro:wheel name="fr_wheel" joint="fr_joint" x="0.2"  y="-0.225"/>
  <xacro:wheel name="rl_wheel" joint="rl_joint" x="-0.2" y="0.225"/>
  <xacro:wheel name="rr_wheel" joint="rr_joint" x="-0.2" y="-0.225"/>

</robot>